<?xml version="1.0" encoding="utf-8"?>
<!-- =================================================================================== -->
<!-- |    This document was autogenerated by xacro from dlr_hit_15.urdf.xacro                | -->
<!-- |    EDITING THIS FILE BY HAND IS NOT RECOMMENDED                                 | -->
<!-- =================================================================================== -->
<robot name="dlr_hit2">
  <material name="DLR/LightGrey">
    <color rgba="0.7 0.7 0.7 1.0"/>
  </material>
  <material name="DLR/DarkGrey">
    <color rgba="0.4 0.4 0.4 1.0"/>
  </material>
  <material name="DLR/Black">
    <color rgba="0.0 0.0 0.0 1.0"/>
  </material>
  <material name="DLR/DarkGolden">
    <color rgba="0.4 0.4 0.3 1.0"/>
  </material>
  <material name="DLR/Blue">
    <color rgba="0.0 0.0 0.8 1.0"/>
  </material>
  <link name="root">
    <inertial>
      <origin rpy="-0.03143 -0.00602 -0.37822" xyz="0.00100 -0.00200 0.29000"/>
      <mass value="4.00000"/>
      <inertia ixx="0.05139" ixy="0" ixz="0" iyy="0.05015" iyz="0" izz="0.04715"/>
    </inertial>
  </link>
  <link name="root1">
    <inertial>
      <mass value="0.01"/>
      <inertia ixx="1e-4" ixy="0.0" ixz="0.0" iyy="1e-4" iyz="0.0" izz="1e-4"/>
    </inertial>
  </link>
  <link name="root2">
    <inertial>
      <mass value="0.01"/>
      <inertia ixx="1e-4" ixy="0.0" ixz="0.0" iyy="1e-4" iyz="0.0" izz="1e-4"/>
    </inertial>
  </link>
  <link name="root3">
    <inertial>
      <mass value="0.01"/>
      <inertia ixx="1e-4" ixy="0.0" ixz="0.0" iyy="1e-4" iyz="0.0" izz="1e-4"/>
    </inertial>
  </link>
  <link name="root4">
    <inertial>
      <mass value="0.01"/>
      <inertia ixx="1e-4" ixy="0.0" ixz="0.0" iyy="1e-4" iyz="0.0" izz="1e-4"/>
    </inertial>
  </link>
  <link name="root5">
    <inertial>
      <mass value="0.01"/>
      <inertia ixx="1e-4" ixy="0.0" ixz="0.0" iyy="1e-4" iyz="0.0" izz="1e-4"/>
    </inertial>
  </link>

  <joint name="x_joint" type="prismatic">
    <parent link="root"/>
    <child link="root1"/>
    <axis xyz="1 0 0"/>
    <limit lower="-5" upper="5"/>
  </joint>
  <joint name="y_joint" type="prismatic">
    <parent link="root1"/>
    <child link="root2"/>
    <axis xyz="0 1 0"/>
    <limit lower="-5" upper="5"/>
  </joint>
  <joint name="z_joint" type="prismatic">
    <parent link="root2"/>
    <child link="root3"/>
    <axis xyz="0 0 1"/>
    <limit lower="-5" upper="5"/>
  </joint>
  <joint name="x_rotation_joint" type="revolute">
    <parent link="root3"/>
    <child link="root4"/>
    <axis xyz="1 0 0"/>
    <limit lower="-3.14" upper="3.14"/>
  </joint>
  <joint name="y_rotation_joint" type="revolute">
    <parent link="root4"/>
    <child link="root5"/>
    <axis xyz="0 1 0"/>
    <limit lower="-3.14" upper="3.14"/>
  </joint>
  <joint name="z_rotation_joint" type="revolute">
    <parent link="root5"/>
    <child link="right_palm_link"/>
    <axis xyz="0 0 1"/>
    <origin rpy="-0.00000 -0.00000 1.57079" xyz="0 0 0"/>
    <limit lower="-3.14" upper="3.14"/>
  </joint>

  <!-- macro for the hand -->
  <!-- joint between arm_end_effector and hit2_palm_link -->
  <link name="right_palm_link">
    <!-- <inertial> -->
    <!-- PALM MASS AND INERTIA TO BE ESTIMATED!!!! -->
    <!-- <origin xyz="0 0 0" rpy="0 0 0"/>
				<mass value="1"/>
				<inertia ixx="0.01" ixy="0" ixz="0" iyy="0.01" iyz="0" izz="0.01" />
			</inertial> -->
    <!-- also check whether is ok to leave at zero the origin -->
    <visual>
      <origin rpy="0 0 0" xyz="0 0 0"/>
      <geometry>
        <mesh filename="dlr_description/meshes/hit2/palm.stl"/>
      </geometry>
      <material name="DLR/LightGrey"/>
    </visual>
    <collision>
      <origin rpy="0 0 0" xyz="0 0 0"/>
      <geometry>
        <mesh filename="dlr_description/meshes/hit2/palm.stl"/>
      </geometry>
    </collision>
  </link>
  <!-- macro for one finger -->
  <!-- abductor joint between palm_link and finger_abd_link - fake between palm and proximal -->
  <joint name="right_thumb_abd_joint" type="revolute">
    <origin rpy="0.41136 -1.08366 0.225804" xyz="0.062569057 0.044544548 0.080044647"/>
    <parent link="right_palm_link"/>
    <child link="right_thumb_abd_link"/>
    <axis xyz="0 0 1"/>
    <dynamics damping="1"/>
    <limit effort="100" lower="-0.349065850399" upper="0.349065850399" velocity="5"/>
    <!-- effort="100" velocity="5" -->
  </joint>
  <link name="right_thumb_abd_link">
    <!-- 			<inertial>
				<origin xyz="0 0 0" rpy="0 0 0"/>
				<mass value="0.0"/>
				<inertia ixx="0" ixy="0" ixz="0" iyy="0" iyz="0" izz="0" />
			</inertial> -->
    <!-- possibly add basecover.stl as both geometry and collision... -->
    <visual>
      <origin rpy="0 0 0" xyz="0 0 0"/>
      <geometry>
        <mesh filename="dlr_description/meshes/hit2/base.stl"/>
      </geometry>
      <material name="DLR/LightGrey"/>
    </visual>
  </link>
  <!-- inner joint between abd_link and proximal_link -->
  <joint name="right_thumb_inner_joint" type="revolute">
    <!-- coincident with abd_joint, rotated of 90 degrees along x -->
    <origin rpy="1.57079632679 0 0" xyz="0 0 0"/>
    <parent link="right_thumb_abd_link"/>
    <child link="right_thumb_proximal_link"/>
    <axis xyz="0 0 1"/>
    <dynamics damping="1"/>
    <limit effort="100" lower="0.0" upper="1.308996939" velocity="5"/>
    <!-- effort="100" velocity="5" -->
  </joint>
  <link name="right_thumb_proximal_link">
    <!-- <inertial>
				<origin xyz="30.164510e -1.0130813 0.50813186" rpy="0 0 0"/>
				<mass value="0.044370598"/>
				<inertia ixx="${inertia_scale * 4.5592704}" ixy="${inertia_scale * 0.90783105}" ixz="${inertia_scale * (-0.9399771)}" iyy="${inertia_scale * 49.045259}" iyz="${inertia_scale * 0.017052714}" izz="${inertia_scale * 50.524234}" />
			</inertial> -->
    <visual>
      <origin rpy="0 0 0" xyz="0 0 0"/>
      <geometry>
        <mesh filename="dlr_description/meshes/hit2/proximal.stl"/>
      </geometry>
      <material name="DLR/LightGrey"/>
    </visual>
    <!-- 			<collision>
				<origin xyz="0 0 0" rpy="0 0 0" />
				<geometry>
					<mesh filename="dlr_description/meshes/hit2/phalanx_proximal.stl"/>
				</geometry>
			</collision> -->
  </link>
  <!-- outer1 joint between proximal_link and medial_link -->
  <joint name="right_thumb_outer1_joint" type="revolute">
    <origin rpy="0 0 0" xyz="0.055 0 0"/>
    <parent link="right_thumb_proximal_link"/>
    <child link="right_thumb_medial_link"/>
    <axis xyz="0 0 1"/>
    <dynamics damping="1"/>
    <limit effort="100" lower="0.0" upper="1.308996939" velocity="5"/>
    <!-- effort="100" velocity="5" -->
  </joint>
  <link name="right_thumb_medial_link">
    <!-- <inertial>
			<origin xyz="5.7271879 -1.6164173 -1.1567914" rpy="0 0 0"/>
				<mass value="0.027110192"/>
				<inertia ixx="${inertia_scale * 2.2900229}" ixy="${inertia_scale * 0.40604622}" ixz="${inertia_scale * 0.14362094}" iyy="${inertia_scale * 4.2155489}" iyz="${inertia_scale * (-0.043115648)}" izz="${inertia_scale * 4.4292927}" />
			</inertial> -->
    <visual>
      <origin rpy="0 0 0" xyz="0 0 0"/>
      <geometry>
        <mesh filename="dlr_description/meshes/hit2/medial.stl"/>
      </geometry>
      <material name="DLR/LightGrey"/>
    </visual>
    <collision>
      <origin rpy="0 0 0" xyz="0 0 0"/>
      <geometry>
        <mesh filename="dlr_description/meshes/hit2/medial.stl"/>
      </geometry>
    </collision>
  </link>
  <!-- outer2 joint between medial_link and distal_link -->
  <joint name="right_thumb_outer2_joint" type="revolute">
    <origin rpy="0 0 -1.57079632679" xyz="0.025 0 0"/>
    <parent link="right_thumb_medial_link"/>
    <child link="right_thumb_distal_link"/>
    <axis xyz="0 0 1"/>
    <dynamics damping="1"/>
    <limit effort="100" lower="0.0" upper="1.308996939" velocity="5"/>
    <!-- effort="100" velocity="5" -->
  </joint>
  <link name="right_thumb_distal_link">
    <!-- <inertial>
			<origin xyz="-0.83348211 6.1007977 1.7728256" rpy="0 0 0"/>
				<mass value="0.018179709"/>
				<inertia ixx="${inertia_scale * 2.5867271}" ixy="${inertia_scale * 0.15840536}" ixz="${inertia_scale * (-0.00078205885)}" iyy="${inertia_scale * 0.84596248}" iyz="${inertia_scale * (-0.0048358115)}" izz="${inertia_scale * 2.5838485}" />
			</inertial> -->
    <visual>
      <origin rpy="0 0 0" xyz="0 0 0"/>
      <geometry>
        <mesh filename="dlr_description/meshes/hit2/distal.stl"/>
      </geometry>
      <material name="DLR/LightGrey"/>
    </visual>
    <collision>
      <origin rpy="0 0 0" xyz="0 0 0"/>
      <geometry>
        <mesh filename="dlr_description/meshes/hit2/distal.stl"/>
      </geometry>
    </collision>
  </link>
  <!-- macro for one finger -->
  <!-- abductor joint between palm_link and finger_abd_link - fake between palm and proximal -->
  <joint name="right_index_abd_joint" type="revolute">
    <origin rpy="3.05433 -1.57079632679 0" xyz="-0.002529881 0.036800135 0.108743545"/>
    <parent link="right_palm_link"/>
    <child link="right_index_abd_link"/>
    <axis xyz="0 0 1"/>
    <dynamics damping="1"/>
    <limit effort="100" lower="-0.349065850399" upper="0.349065850399" velocity="5"/>
    <!-- effort="100" velocity="5" -->
  </joint>
  <link name="right_index_abd_link">
    <!-- 			<inertial>
				<origin xyz="0 0 0" rpy="0 0 0"/>
				<mass value="0.0"/>
				<inertia ixx="0" ixy="0" ixz="0" iyy="0" iyz="0" izz="0" />
			</inertial> -->
    <!-- possibly add basecover.stl as both geometry and collision... -->
    <visual>
      <origin rpy="0 0 0" xyz="0 0 0"/>
      <geometry>
        <mesh filename="dlr_description/meshes/hit2/base.stl"/>
      </geometry>
      <material name="DLR/LightGrey"/>
    </visual>
  </link>
  <!-- inner joint between abd_link and proximal_link -->
  <joint name="right_index_inner_joint" type="revolute">
    <!-- coincident with abd_joint, rotated of 90 degrees along x -->
    <origin rpy="1.57079632679 0 0" xyz="0 0 0"/>
    <parent link="right_index_abd_link"/>
    <child link="right_index_proximal_link"/>
    <axis xyz="0 0 1"/>
    <dynamics damping="1"/>
    <limit effort="100" lower="0.0" upper="1.308996939" velocity="5"/>
    <!-- effort="100" velocity="5" -->
  </joint>
  <link name="right_index_proximal_link">
    <!-- <inertial>
				<origin xyz="30.164510e -1.0130813 0.50813186" rpy="0 0 0"/>
				<mass value="0.044370598"/>
				<inertia ixx="${inertia_scale * 4.5592704}" ixy="${inertia_scale * 0.90783105}" ixz="${inertia_scale * (-0.9399771)}" iyy="${inertia_scale * 49.045259}" iyz="${inertia_scale * 0.017052714}" izz="${inertia_scale * 50.524234}" />
			</inertial> -->
    <visual>
      <origin rpy="0 0 0" xyz="0 0 0"/>
      <geometry>
        <mesh filename="dlr_description/meshes/hit2/proximal.stl"/>
      </geometry>
      <material name="DLR/LightGrey"/>
    </visual>
    <!-- 			<collision>
				<origin xyz="0 0 0" rpy="0 0 0" />
				<geometry>
					<mesh filename="dlr_description/meshes/hit2/phalanx_proximal.stl"/>
				</geometry>
			</collision> -->
  </link>
  <!-- outer1 joint between proximal_link and medial_link -->
  <joint name="right_index_outer1_joint" type="revolute">
    <origin rpy="0 0 0" xyz="0.055 0 0"/>
    <parent link="right_index_proximal_link"/>
    <child link="right_index_medial_link"/>
    <axis xyz="0 0 1"/>
    <dynamics damping="1"/>
    <limit effort="100" lower="0.0" upper="1.308996939" velocity="5"/>
    <!-- effort="100" velocity="5" -->
  </joint>
  <link name="right_index_medial_link">
    <!-- <inertial>
			<origin xyz="5.7271879 -1.6164173 -1.1567914" rpy="0 0 0"/>
				<mass value="0.027110192"/>
				<inertia ixx="${inertia_scale * 2.2900229}" ixy="${inertia_scale * 0.40604622}" ixz="${inertia_scale * 0.14362094}" iyy="${inertia_scale * 4.2155489}" iyz="${inertia_scale * (-0.043115648)}" izz="${inertia_scale * 4.4292927}" />
			</inertial> -->
    <visual>
      <origin rpy="0 0 0" xyz="0 0 0"/>
      <geometry>
        <mesh filename="dlr_description/meshes/hit2/medial.stl"/>
      </geometry>
      <material name="DLR/LightGrey"/>
    </visual>
    <collision>
      <origin rpy="0 0 0" xyz="0 0 0"/>
      <geometry>
        <mesh filename="dlr_description/meshes/hit2/medial.stl"/>
      </geometry>
    </collision>
  </link>
  <!-- outer2 joint between medial_link and distal_link -->
  <joint name="right_index_outer2_joint" type="revolute">
    <origin rpy="0 0 -1.57079632679" xyz="0.025 0 0"/>
    <parent link="right_index_medial_link"/>
    <child link="right_index_distal_link"/>
    <axis xyz="0 0 1"/>
    <dynamics damping="1"/>
    <limit effort="100" lower="0.0" upper="1.308996939" velocity="5"/>
    <!-- effort="100" velocity="5" -->
  </joint>
  <link name="right_index_distal_link">
    <!-- <inertial>
			<origin xyz="-0.83348211 6.1007977 1.7728256" rpy="0 0 0"/>
				<mass value="0.018179709"/>
				<inertia ixx="${inertia_scale * 2.5867271}" ixy="${inertia_scale * 0.15840536}" ixz="${inertia_scale * (-0.00078205885)}" iyy="${inertia_scale * 0.84596248}" iyz="${inertia_scale * (-0.0048358115)}" izz="${inertia_scale * 2.5838485}" />
			</inertial> -->
    <visual>
      <origin rpy="0 0 0" xyz="0 0 0"/>
      <geometry>
        <mesh filename="dlr_description/meshes/hit2/distal.stl"/>
      </geometry>
      <material name="DLR/LightGrey"/>
    </visual>
    <collision>
      <origin rpy="0 0 0" xyz="0 0 0"/>
      <geometry>
        <mesh filename="dlr_description/meshes/hit2/distal.stl"/>
      </geometry>
    </collision>
  </link>
  <!-- macro for one finger -->
  <!-- abductor joint between palm_link and finger_abd_link - fake between palm and proximal -->
  <joint name="right_middle_abd_joint" type="revolute">
    <origin rpy="3.14159265359 -1.57079632679 0" xyz="-0.0037 0.01 0.119043545"/>
    <parent link="right_palm_link"/>
    <child link="right_middle_abd_link"/>
    <axis xyz="0 0 1"/>
    <dynamics damping="1"/>
    <limit effort="100" lower="-0.349065850399" upper="0.349065850399" velocity="5"/>
    <!-- effort="100" velocity="5" -->
  </joint>
  <link name="right_middle_abd_link">
    <!-- 			<inertial>
				<origin xyz="0 0 0" rpy="0 0 0"/>
				<mass value="0.0"/>
				<inertia ixx="0" ixy="0" ixz="0" iyy="0" iyz="0" izz="0" />
			</inertial> -->
    <!-- possibly add basecover.stl as both geometry and collision... -->
    <visual>
      <origin rpy="0 0 0" xyz="0 0 0"/>
      <geometry>
        <mesh filename="dlr_description/meshes/hit2/base.stl"/>
      </geometry>
      <material name="DLR/LightGrey"/>
    </visual>
  </link>
  <!-- inner joint between abd_link and proximal_link -->
  <joint name="right_middle_inner_joint" type="revolute">
    <!-- coincident with abd_joint, rotated of 90 degrees along x -->
    <origin rpy="1.57079632679 0 0" xyz="0 0 0"/>
    <parent link="right_middle_abd_link"/>
    <child link="right_middle_proximal_link"/>
    <axis xyz="0 0 1"/>
    <dynamics damping="1"/>
    <limit effort="100" lower="0.0" upper="1.308996939" velocity="5"/>
    <!-- effort="100" velocity="5" -->
  </joint>
  <link name="right_middle_proximal_link">
    <!-- <inertial>
				<origin xyz="30.164510e -1.0130813 0.50813186" rpy="0 0 0"/>
				<mass value="0.044370598"/>
				<inertia ixx="${inertia_scale * 4.5592704}" ixy="${inertia_scale * 0.90783105}" ixz="${inertia_scale * (-0.9399771)}" iyy="${inertia_scale * 49.045259}" iyz="${inertia_scale * 0.017052714}" izz="${inertia_scale * 50.524234}" />
			</inertial> -->
    <visual>
      <origin rpy="0 0 0" xyz="0 0 0"/>
      <geometry>
        <mesh filename="dlr_description/meshes/hit2/proximal.stl"/>
      </geometry>
      <material name="DLR/LightGrey"/>
    </visual>
    <!-- 			<collision>
				<origin xyz="0 0 0" rpy="0 0 0" />
				<geometry>
					<mesh filename="dlr_description/meshes/hit2/phalanx_proximal.stl"/>
				</geometry>
			</collision> -->
  </link>
  <!-- outer1 joint between proximal_link and medial_link -->
  <joint name="right_middle_outer1_joint" type="revolute">
    <origin rpy="0 0 0" xyz="0.055 0 0"/>
    <parent link="right_middle_proximal_link"/>
    <child link="right_middle_medial_link"/>
    <axis xyz="0 0 1"/>
    <dynamics damping="1"/>
    <limit effort="100" lower="0.0" upper="1.308996939" velocity="5"/>
    <!-- effort="100" velocity="5" -->
  </joint>
  <link name="right_middle_medial_link">
    <!-- <inertial>
			<origin xyz="5.7271879 -1.6164173 -1.1567914" rpy="0 0 0"/>
				<mass value="0.027110192"/>
				<inertia ixx="${inertia_scale * 2.2900229}" ixy="${inertia_scale * 0.40604622}" ixz="${inertia_scale * 0.14362094}" iyy="${inertia_scale * 4.2155489}" iyz="${inertia_scale * (-0.043115648)}" izz="${inertia_scale * 4.4292927}" />
			</inertial> -->
    <visual>
      <origin rpy="0 0 0" xyz="0 0 0"/>
      <geometry>
        <mesh filename="dlr_description/meshes/hit2/medial.stl"/>
      </geometry>
      <material name="DLR/LightGrey"/>
    </visual>
    <collision>
      <origin rpy="0 0 0" xyz="0 0 0"/>
      <geometry>
        <mesh filename="dlr_description/meshes/hit2/medial.stl"/>
      </geometry>
    </collision>
  </link>
  <!-- outer2 joint between medial_link and distal_link -->
  <joint name="right_middle_outer2_joint" type="revolute">
    <origin rpy="0 0 -1.57079632679" xyz="0.025 0 0"/>
    <parent link="right_middle_medial_link"/>
    <child link="right_middle_distal_link"/>
    <axis xyz="0 0 1"/>
    <dynamics damping="1"/>
    <limit effort="100" lower="0.0" upper="1.308996939" velocity="5"/>
    <!-- effort="100" velocity="5" -->
  </joint>
  <link name="right_middle_distal_link">
    <!-- <inertial>
			<origin xyz="-0.83348211 6.1007977 1.7728256" rpy="0 0 0"/>
				<mass value="0.018179709"/>
				<inertia ixx="${inertia_scale * 2.5867271}" ixy="${inertia_scale * 0.15840536}" ixz="${inertia_scale * (-0.00078205885)}" iyy="${inertia_scale * 0.84596248}" iyz="${inertia_scale * (-0.0048358115)}" izz="${inertia_scale * 2.5838485}" />
			</inertial> -->
    <visual>
      <origin rpy="0 0 0" xyz="0 0 0"/>
      <geometry>
        <mesh filename="dlr_description/meshes/hit2/distal.stl"/>
      </geometry>
      <material name="DLR/LightGrey"/>
    </visual>
    <collision>
      <origin rpy="0 0 0" xyz="0 0 0"/>
      <geometry>
        <mesh filename="dlr_description/meshes/hit2/distal.stl"/>
      </geometry>
    </collision>
  </link>
  <!-- macro for one finger -->
  <!-- abductor joint between palm_link and finger_abd_link - fake between palm and proximal -->
  <joint name="right_ring_abd_joint" type="revolute">
    <origin rpy="-3.05433 -1.57079632679 0" xyz="-0.002529881 -0.016800135 0.114043545"/>
    <parent link="right_palm_link"/>
    <child link="right_ring_abd_link"/>
    <axis xyz="0 0 1"/>
    <dynamics damping="1"/>
    <limit effort="100" lower="-0.349065850399" upper="0.349065850399" velocity="5"/>
    <!-- effort="100" velocity="5" -->
  </joint>
  <link name="right_ring_abd_link">
    <!-- 			<inertial>
				<origin xyz="0 0 0" rpy="0 0 0"/>
				<mass value="0.0"/>
				<inertia ixx="0" ixy="0" ixz="0" iyy="0" iyz="0" izz="0" />
			</inertial> -->
    <!-- possibly add basecover.stl as both geometry and collision... -->
    <visual>
      <origin rpy="0 0 0" xyz="0 0 0"/>
      <geometry>
        <mesh filename="dlr_description/meshes/hit2/base.stl"/>
      </geometry>
      <material name="DLR/LightGrey"/>
    </visual>
  </link>
  <!-- inner joint between abd_link and proximal_link -->
  <joint name="right_ring_inner_joint" type="revolute">
    <!-- coincident with abd_joint, rotated of 90 degrees along x -->
    <origin rpy="1.57079632679 0 0" xyz="0 0 0"/>
    <parent link="right_ring_abd_link"/>
    <child link="right_ring_proximal_link"/>
    <axis xyz="0 0 1"/>
    <dynamics damping="1"/>
    <limit effort="100" lower="0.0" upper="1.308996939" velocity="5"/>
    <!-- effort="100" velocity="5" -->
  </joint>
  <link name="right_ring_proximal_link">
    <!-- <inertial>
				<origin xyz="30.164510e -1.0130813 0.50813186" rpy="0 0 0"/>
				<mass value="0.044370598"/>
				<inertia ixx="${inertia_scale * 4.5592704}" ixy="${inertia_scale * 0.90783105}" ixz="${inertia_scale * (-0.9399771)}" iyy="${inertia_scale * 49.045259}" iyz="${inertia_scale * 0.017052714}" izz="${inertia_scale * 50.524234}" />
			</inertial> -->
    <visual>
      <origin rpy="0 0 0" xyz="0 0 0"/>
      <geometry>
        <mesh filename="dlr_description/meshes/hit2/proximal.stl"/>
      </geometry>
      <material name="DLR/LightGrey"/>
    </visual>
    <!-- 			<collision>
				<origin xyz="0 0 0" rpy="0 0 0" />
				<geometry>
					<mesh filename="dlr_description/meshes/hit2/phalanx_proximal.stl"/>
				</geometry>
			</collision> -->
  </link>
  <!-- outer1 joint between proximal_link and medial_link -->
  <joint name="right_ring_outer1_joint" type="revolute">
    <origin rpy="0 0 0" xyz="0.055 0 0"/>
    <parent link="right_ring_proximal_link"/>
    <child link="right_ring_medial_link"/>
    <axis xyz="0 0 1"/>
    <dynamics damping="1"/>
    <limit effort="100" lower="0.0" upper="1.308996939" velocity="5"/>
    <!-- effort="100" velocity="5" -->
  </joint>
  <link name="right_ring_medial_link">
    <!-- <inertial>
			<origin xyz="5.7271879 -1.6164173 -1.1567914" rpy="0 0 0"/>
				<mass value="0.027110192"/>
				<inertia ixx="${inertia_scale * 2.2900229}" ixy="${inertia_scale * 0.40604622}" ixz="${inertia_scale * 0.14362094}" iyy="${inertia_scale * 4.2155489}" iyz="${inertia_scale * (-0.043115648)}" izz="${inertia_scale * 4.4292927}" />
			</inertial> -->
    <visual>
      <origin rpy="0 0 0" xyz="0 0 0"/>
      <geometry>
        <mesh filename="dlr_description/meshes/hit2/medial.stl"/>
      </geometry>
      <material name="DLR/LightGrey"/>
    </visual>
    <collision>
      <origin rpy="0 0 0" xyz="0 0 0"/>
      <geometry>
        <mesh filename="dlr_description/meshes/hit2/medial.stl"/>
      </geometry>
    </collision>
  </link>
  <!-- outer2 joint between medial_link and distal_link -->
  <joint name="right_ring_outer2_joint" type="revolute">
    <origin rpy="0 0 -1.57079632679" xyz="0.025 0 0"/>
    <parent link="right_ring_medial_link"/>
    <child link="right_ring_distal_link"/>
    <axis xyz="0 0 1"/>
    <dynamics damping="1"/>
    <limit effort="100" lower="0.0" upper="1.308996939" velocity="5"/>
    <!-- effort="100" velocity="5" -->
  </joint>
  <link name="right_ring_distal_link">
    <!-- <inertial>
			<origin xyz="-0.83348211 6.1007977 1.7728256" rpy="0 0 0"/>
				<mass value="0.018179709"/>
				<inertia ixx="${inertia_scale * 2.5867271}" ixy="${inertia_scale * 0.15840536}" ixz="${inertia_scale * (-0.00078205885)}" iyy="${inertia_scale * 0.84596248}" iyz="${inertia_scale * (-0.0048358115)}" izz="${inertia_scale * 2.5838485}" />
			</inertial> -->
    <visual>
      <origin rpy="0 0 0" xyz="0 0 0"/>
      <geometry>
        <mesh filename="dlr_description/meshes/hit2/distal.stl"/>
      </geometry>
      <material name="DLR/LightGrey"/>
    </visual>
    <collision>
      <origin rpy="0 0 0" xyz="0 0 0"/>
      <geometry>
        <mesh filename="dlr_description/meshes/hit2/distal.stl"/>
      </geometry>
    </collision>
  </link>
  <!-- macro for one finger -->
  <!-- abductor joint between palm_link and finger_abd_link - fake between palm and proximal -->
  <joint name="right_pinky_abd_joint" type="revolute">
    <origin rpy="-2.96706 -1.57079632679 0" xyz="0.000971571 -0.043396306 0.095043545"/>
    <parent link="right_palm_link"/>
    <child link="right_pinky_abd_link"/>
    <axis xyz="0 0 1"/>
    <dynamics damping="1"/>
    <limit effort="100" lower="-0.349065850399" upper="0.349065850399" velocity="5"/>
    <!-- effort="100" velocity="5" -->
  </joint>
  <link name="right_pinky_abd_link">
    <!-- 			<inertial>
				<origin xyz="0 0 0" rpy="0 0 0"/>
				<mass value="0.0"/>
				<inertia ixx="0" ixy="0" ixz="0" iyy="0" iyz="0" izz="0" />
			</inertial> -->
    <!-- possibly add basecover.stl as both geometry and collision... -->
    <visual>
      <origin rpy="0 0 0" xyz="0 0 0"/>
      <geometry>
        <mesh filename="dlr_description/meshes/hit2/base.stl"/>
      </geometry>
      <material name="DLR/LightGrey"/>
    </visual>
  </link>
  <!-- inner joint between abd_link and proximal_link -->
  <joint name="right_pinky_inner_joint" type="revolute">
    <!-- coincident with abd_joint, rotated of 90 degrees along x -->
    <origin rpy="1.57079632679 0 0" xyz="0 0 0"/>
    <parent link="right_pinky_abd_link"/>
    <child link="right_pinky_proximal_link"/>
    <axis xyz="0 0 1"/>
    <dynamics damping="1"/>
    <limit effort="100" lower="0.0" upper="1.308996939" velocity="5"/>
    <!-- effort="100" velocity="5" -->
  </joint>
  <link name="right_pinky_proximal_link">
    <!-- <inertial>
				<origin xyz="30.164510e -1.0130813 0.50813186" rpy="0 0 0"/>
				<mass value="0.044370598"/>
				<inertia ixx="${inertia_scale * 4.5592704}" ixy="${inertia_scale * 0.90783105}" ixz="${inertia_scale * (-0.9399771)}" iyy="${inertia_scale * 49.045259}" iyz="${inertia_scale * 0.017052714}" izz="${inertia_scale * 50.524234}" />
			</inertial> -->
    <visual>
      <origin rpy="0 0 0" xyz="0 0 0"/>
      <geometry>
        <mesh filename="dlr_description/meshes/hit2/proximal.stl"/>
      </geometry>
      <material name="DLR/LightGrey"/>
    </visual>
    <!-- 			<collision>
				<origin xyz="0 0 0" rpy="0 0 0" />
				<geometry>
					<mesh filename="dlr_description/meshes/hit2/phalanx_proximal.stl"/>
				</geometry>
			</collision> -->
  </link>
  <!-- outer1 joint between proximal_link and medial_link -->
  <joint name="right_pinky_outer1_joint" type="revolute">
    <origin rpy="0 0 0" xyz="0.055 0 0"/>
    <parent link="right_pinky_proximal_link"/>
    <child link="right_pinky_medial_link"/>
    <axis xyz="0 0 1"/>
    <dynamics damping="1"/>
    <limit effort="100" lower="0.0" upper="1.308996939" velocity="5"/>
    <!-- effort="100" velocity="5" -->
  </joint>
  <link name="right_pinky_medial_link">
    <!-- <inertial>
			<origin xyz="5.7271879 -1.6164173 -1.1567914" rpy="0 0 0"/>
				<mass value="0.027110192"/>
				<inertia ixx="${inertia_scale * 2.2900229}" ixy="${inertia_scale * 0.40604622}" ixz="${inertia_scale * 0.14362094}" iyy="${inertia_scale * 4.2155489}" iyz="${inertia_scale * (-0.043115648)}" izz="${inertia_scale * 4.4292927}" />
			</inertial> -->
    <visual>
      <origin rpy="0 0 0" xyz="0 0 0"/>
      <geometry>
        <mesh filename="dlr_description/meshes/hit2/medial.stl"/>
      </geometry>
      <material name="DLR/LightGrey"/>
    </visual>
    <collision>
      <origin rpy="0 0 0" xyz="0 0 0"/>
      <geometry>
        <mesh filename="dlr_description/meshes/hit2/medial.stl"/>
      </geometry>
    </collision>
  </link>
  <!-- outer2 joint between medial_link and distal_link -->
  <joint name="right_pinky_outer2_joint" type="revolute">
    <origin rpy="0 0 -1.57079632679" xyz="0.025 0 0"/>
    <parent link="right_pinky_medial_link"/>
    <child link="right_pinky_distal_link"/>
    <axis xyz="0 0 1"/>
    <dynamics damping="1"/>
    <limit effort="100" lower="0.0" upper="1.308996939" velocity="5"/>
    <!-- effort="100" velocity="5" -->
  </joint>
  <link name="right_pinky_distal_link">
    <!-- <inertial>
			<origin xyz="-0.83348211 6.1007977 1.7728256" rpy="0 0 0"/>
				<mass value="0.018179709"/>
				<inertia ixx="${inertia_scale * 2.5867271}" ixy="${inertia_scale * 0.15840536}" ixz="${inertia_scale * (-0.00078205885)}" iyy="${inertia_scale * 0.84596248}" iyz="${inertia_scale * (-0.0048358115)}" izz="${inertia_scale * 2.5838485}" />
			</inertial> -->
    <visual>
      <origin rpy="0 0 0" xyz="0 0 0"/>
      <geometry>
        <mesh filename="dlr_description/meshes/hit2/distal.stl"/>
      </geometry>
      <material name="DLR/LightGrey"/>
    </visual>
    <collision>
      <origin rpy="0 0 0" xyz="0 0 0"/>
      <geometry>
        <mesh filename="dlr_description/meshes/hit2/distal.stl"/>
      </geometry>
    </collision>
  </link>
  <!-- five equal fingers -->
</robot>