<?xml version="1.0" encoding="utf-8"?>
<!-- =================================================================================== -->
<!-- |    This document was autogenerated by xacro from panda_arm_hand.urdf.xacro      | -->
<!-- |    EDITING THIS FILE BY HAND IS NOT RECOMMENDED                                 | -->
<!-- =================================================================================== -->
<robot name="panda" xmlns:xacro="http://www.ros.org/wiki/xacro">
  <link name="panda_root0">
    <inertial>
      <origin rpy="-0.03143 -0.00602 -0.37822" xyz="0.00100 -0.00200 0.29000"/>
      <mass value="4.00000"/>
      <inertia ixx="0.05139" ixy="0" ixz="0" iyy="0.05015" iyz="0" izz="0.04715"/>
    </inertial>
  </link>
  <link name="panda_root1">
    <inertial>
      <mass value="0.01"/>
      <inertia ixx="1e-4" ixy="0.0" ixz="0.0" iyy="1e-4" iyz="0.0" izz="1e-4"/>
    </inertial>
  </link>
  <link name="panda_root2">
    <inertial>
      <mass value="0.01"/>
      <inertia ixx="1e-4" ixy="0.0" ixz="0.0" iyy="1e-4" iyz="0.0" izz="1e-4"/>
    </inertial>
  </link>
  <link name="panda_root3">
    <inertial>
      <mass value="0.01"/>
      <inertia ixx="1e-4" ixy="0.0" ixz="0.0" iyy="1e-4" iyz="0.0" izz="1e-4"/>
    </inertial>
  </link>
  <link name="panda_root4">
    <inertial>
      <mass value="0.01"/>
      <inertia ixx="1e-4" ixy="0.0" ixz="0.0" iyy="1e-4" iyz="0.0" izz="1e-4"/>
    </inertial>
  </link>
  <link name="panda_root5">
    <inertial>
      <mass value="0.01"/>
      <inertia ixx="1e-4" ixy="0.0" ixz="0.0" iyy="1e-4" iyz="0.0" izz="1e-4"/>
    </inertial>
  </link>

  <joint name="x_joint" type="prismatic">
    <parent link="panda_root0"/>
    <child link="panda_root1"/>
    <axis xyz="1 0 0"/>
    <limit lower="-0.5" upper="0.5"/>
  </joint>
  <joint name="y_joint" type="prismatic">
    <parent link="panda_root1"/>
    <child link="panda_root2"/>
    <axis xyz="0 1 0"/>
    <limit lower="-0.5" upper="0.5"/>
  </joint>
  <joint name="z_joint" type="prismatic">
    <parent link="panda_root2"/>
    <child link="panda_root3"/>
    <axis xyz="0 0 1"/>
    <limit lower="-0.5" upper="0.5"/>
  </joint>
  <joint name="x_rotation_joint" type="revolute">
    <parent link="panda_root3"/>
    <child link="panda_root4"/>
    <axis xyz="1 0 0"/>
    <limit lower="-3.14" upper="3.14"/>
  </joint>
  <joint name="y_rotation_joint" type="revolute">
    <parent link="panda_root4"/>
    <child link="panda_root5"/>
    <axis xyz="0 1 0"/>
    <limit lower="-3.14" upper="3.14"/>
  </joint>
  <joint name="z_rotation_joint" type="revolute">
    <parent link="panda_root5"/>
    <child link="panda_hand"/>
    <axis xyz="0 0 1"/>
    <origin rpy="-0.00000 -0.00000 0" xyz="0 0 0"/>
    <limit lower="-3.14" upper="3.14"/>
  </joint>

  <link name="panda_hand">
    <visual>
      <geometry>
        <mesh filename="franka_description/meshes/visual/hand.dae" />
      </geometry>
    </visual>
    <collision>
      <geometry>
        <mesh filename="franka_description/meshes/collision/hand.stl" />
      </geometry>
    </collision>
  </link>
  <link name="panda_leftfinger">
    <visual>
      <geometry>
        <mesh filename="franka_description/meshes/visual/finger.dae" />
      </geometry>
    </visual>
    <collision>
      <origin xyz="0 0.0072 0.044862" />
      <geometry>
        <box size="0.017088 0.01466 0.017088" />
      </geometry>
    </collision>
    <collision>
      <origin xyz="0 0.018361 0.011482" />
      <geometry>
        <box size="0.020466 0.015156 0.01515" />
      </geometry>
    </collision>
    <collision>
      <origin xyz="0 0.016462 0.027801" rpy="0.5280214399228524 0 0" />
      <geometry>
        <box size="0.020984 0.006538 0.02391" />
      </geometry>
    </collision>
  </link>
  <link name="panda_rightfinger">
    <visual>
      <origin rpy="0 0 3.14159265359" xyz="0 0 0" />
      <geometry>
        <mesh filename="franka_description/meshes/visual/finger.dae" />
      </geometry>
    </visual>
    <collision>
      <origin xyz="0 -0.0072 0.044862" />
      <geometry>
        <box size="0.017088 0.01466 0.017088" />
      </geometry>
    </collision>
    <collision>
      <origin xyz="0 -0.018361 0.011482" />
      <geometry>
        <box size="0.020466 0.015156 0.01515" />
      </geometry>
    </collision>
    <collision>
      <origin xyz="0 -0.016462 0.027801" rpy="0.5280214399228524 0 3.14159265359" />
      <geometry>
        <box size="0.020984 0.006538 0.02391" />
      </geometry>
    </collision>
  </link>
  <joint name="panda_finger_joint1" type="prismatic">
    <parent link="panda_hand" />
    <child link="panda_leftfinger" />
    <origin rpy="0 0 0" xyz="0 0 0.0584" />
    <axis xyz="0 1 0" />
    <limit effort="20" lower="0.0" upper="0.04" velocity="0.2" />
  </joint>
  <joint name="panda_finger_joint2" type="prismatic">
    <parent link="panda_hand" />
    <child link="panda_rightfinger" />
    <origin rpy="0 0 0" xyz="0 0 0.0584" />
    <axis xyz="0 -1 0" />
    <limit effort="20" lower="0.0" upper="0.04" velocity="0.2" />
    <mimic joint="panda_finger_joint1" />
  </joint>
  <link name="grasp_site" />
  <joint name="grasp_site_joint" type="fixed">
    <origin rpy="0 0 0" xyz="0 0 0.103" />
    <parent link="panda_hand" />
    <child link="grasp_site" />
  </joint>
</robot>